#VRML_SIM R2023b utf8

EXTERNPROTO "https://raw.githubusercontent.com/cyberbotics/webots/cb1af9e3bbe43a138b70fe67552cfcc8c7fe1e11/projects/objects/backgrounds/protos/TexturedBackground.proto"
EXTERNPROTO "https://raw.githubusercontent.com/cyberbotics/webots/cb1af9e3bbe43a138b70fe67552cfcc8c7fe1e11/projects/objects/backgrounds/protos/TexturedBackgroundLight.proto"
EXTERNPROTO "https://raw.githubusercontent.com/cyberbotics/webots/cb1af9e3bbe43a138b70fe67552cfcc8c7fe1e11/projects/objects/floors/protos/RectangleArena.proto"

WorldInfo {
  info [
    "Simulation using webots and ZeroROS."
  ]
  title "Simulation ZeroROS"
  basicTimeStep 8
  lineScale 0.15
  contactProperties [
    DEF MaxFric ContactProperties {
      material1 "roboWheel"
      coulombFriction [
        -1
      ]
      bounce 0
    }
    DEF NoFric ContactProperties {
      material2 "robo_body"
      coulombFriction [
        0
      ]
      bounce 0
    }
  ]
}
Viewpoint {
  orientation -0.005398042650515628 0.9999705508825947 0.005455135479832842 1.5608286177774473
  position 0.7991353949552814 1.3216935101988379 11.332113061398669
  follow "MyBot"
}
TexturedBackground {
  skybox FALSE
}
TexturedBackgroundLight {
}
RectangleArena {
  floorSize 10 10
  floorTileSize 2 2
  wallThickness 0.5
  wallHeight 0.5
}
DEF PINK_OBJECT3 Solid {
  translation -2 -2 0.39
  children [
    DEF CYLINDER_SHAPE Shape {
      appearance PBRAppearance {
        baseColor 1 0.1 0.3
        roughness 0.16827074099999995
        metalness 0
      }
      geometry Cylinder {
        height 0.8
        radius 0.15
        subdivision 20
      }
    }
  ]
  name "pink object 3"
  boundingObject DEF PCYL Shape {
    appearance PBRAppearance {
      baseColor 1 0.1 0.3
      roughness 0.16827074099999995
      metalness 0
    }
    geometry DEF PCYL Cylinder {
      height 0.8
      radius 0.15
      subdivision 20
    }
  }
}
DEF PINK_OBJECT3 Solid {
  translation 2 -2 0.4
  children [
    DEF CYLINDER_SHAPE Shape {
      appearance PBRAppearance {
        baseColor 1 0.1 0.3
        roughness 0.16827074099999995
        metalness 0
      }
      geometry Cylinder {
        height 0.8
        radius 0.15
        subdivision 20
      }
    }
  ]
  name "pink object 3(3)"
  boundingObject DEF PCYL Shape {
    appearance PBRAppearance {
      baseColor 1 0.1 0.3
      roughness 0.16827074099999995
      metalness 0
    }
    geometry DEF PCYL Cylinder {
      height 0.8
      radius 0.15
      subdivision 20
    }
  }
}
DEF PINK_OBJECT3 Solid {
  translation 2 0 0.39
  children [
    DEF CYLINDER_SHAPE Shape {
      appearance PBRAppearance {
        baseColor 1 0.1 0.3
        roughness 0.16827074099999995
        metalness 0
      }
      geometry DEF PBOX Box {
        size 0.3 0.3 0.8
      }
    }
  ]
  name "pink object 3(4)"
  boundingObject USE PBOX
}
DEF PINK_OBJECT3 Solid {
  translation 0 -2 0.39
  children [
    DEF CYLINDER_SHAPE Shape {
      appearance PBRAppearance {
        baseColor 1 0.1 0.3
        roughness 0.16827074099999995
        metalness 0
      }
      geometry DEF PBOX Box {
        size 0.1 0.3 0.8
      }
    }
  ]
  name "pink object 3(5)"
  boundingObject USE PBOX
}
DEF PINK_OBJECT3 Solid {
  translation 7.34641e-06 -2 0.39
  rotation 0 0 1 1.5708
  children [
    DEF CYLINDER_SHAPE Shape {
      appearance PBRAppearance {
        baseColor 1 0.1 0.3
        roughness 0.16827074099999995
        metalness 0
      }
      geometry DEF PBOX Box {
        size 0.1 0.3 0.8
      }
    }
  ]
  name "pink object 3(8)"
  boundingObject USE PBOX
}
DEF PINK_OBJECT3 Solid {
  translation 0 0 0.39
  children [
    DEF CYLINDER_SHAPE Shape {
      appearance PBRAppearance {
        baseColor 1 0.1 0.3
        roughness 0.16827074099999995
        metalness 0
      }
      geometry DEF PBOX Box {
        size 0.3 0.3 0.8
      }
    }
  ]
  name "pink object 3(2)"
  boundingObject USE PBOX
}
DEF PINK_OBJECT3 Solid {
  translation -2 0 0.39
  children [
    DEF CYLINDER_SHAPE Shape {
      appearance PBRAppearance {
        baseColor 1 0.1 0.3
        roughness 0.16827074099999995
        metalness 0
      }
      geometry Cylinder {
        height 0.8
        radius 0.15
        subdivision 20
      }
    }
  ]
  name "pink object 3(1)"
  boundingObject DEF PCYL Shape {
    appearance PBRAppearance {
      baseColor 1 0.1 0.3
      roughness 0.16827074099999995
      metalness 0
    }
    geometry DEF PCYL Cylinder {
      height 0.8
      radius 0.15
      subdivision 20
    }
  }
}
DEF PINK_OBJECT3 Solid {
  translation -3.98 0.66 0.39
  children [
    DEF CYLINDER_SHAPE Shape {
      appearance PBRAppearance {
        baseColor 1 0.1 0.3
        roughness 0.16827074099999995
        metalness 0
      }
      geometry Cylinder {
        height 0.8
        radius 0.15
        subdivision 20
      }
    }
  ]
  name "pink object 3(6)"
  boundingObject DEF PCYL Shape {
    appearance PBRAppearance {
      baseColor 1 0.1 0.3
      roughness 0.16827074099999995
      metalness 0
    }
    geometry DEF PCYL Cylinder {
      height 0.8
      radius 0.15
      subdivision 20
    }
  }
}
DEF PINK_OBJECT3 Solid {
  translation -3.98 -1.34 0.39
  children [
    DEF CYLINDER_SHAPE Shape {
      appearance PBRAppearance {
        baseColor 1 0.1 0.3
        roughness 0.16827074099999995
        metalness 0
      }
      geometry Cylinder {
        height 0.8
        radius 0.15
        subdivision 20
      }
    }
  ]
  name "pink object 3(7)"
  boundingObject DEF PCYL Shape {
    appearance PBRAppearance {
      baseColor 1 0.1 0.3
      roughness 0.16827074099999995
      metalness 0
    }
    geometry DEF PCYL Cylinder {
      height 0.8
      radius 0.15
      subdivision 20
    }
  }
}
DEF ROBOT Robot {
  translation 1.00428 1.01208 0.0059598
  rotation 0 0 1 -1.5660653071795858
  children [
    Gyro {
    }
    Compass {
    }
    GPS {
    }
    Pose {
      translation 0 0 0.1245
      rotation 0 0 1 -1.570796
      children [
        Shape {
          appearance PBRAppearance {
            baseColor 0.74902 0.74902 0.74902
            roughness 1
            metalness 0
          }
          geometry DEF BODY Cylinder {
            height 0.24
            radius 0.135
          }
        }
      ]
    }
    HingeJoint {
      jointParameters HingeJointParameters {
        position 109.1326572165503
        axis 0 1 0
        anchor 0 0 0.075
      }
      device [
        RotationalMotor {
          name "left wheel motor"
          consumptionFactor 70
          maxVelocity 100
        }
        PositionSensor {
          name "left wheel sensor"
        }
      ]
      endPoint Solid {
        translation 0 0.13499999999998466 0.075
        rotation 0.6492952158314748 -0.6492953991282648 0.3960192007582788 3.8957326918827726
        children [
          DEF WHEEL Pose {
            rotation 0.577656895078166 0.5771968951617173 -0.5771968951617173 -2.093935
            children [
              Shape {
                appearance PBRAppearance {
                  baseColor 0.301961 0.301961 0.301961
                  roughness 1
                  metalness 0
                }
                geometry Cylinder {
                  height 0.0005
                  radius 0.0715
                  subdivision 50
                }
              }
            ]
          }
        ]
        name "left wheel"
        contactMaterial "roboWheel"
        boundingObject USE WHEEL
        physics DEF PHYSICS_WHEEL Physics {
          density -1
          mass 0.05
        }
      }
    }
    HingeJoint {
      jointParameters HingeJointParameters {
        position 97.96504738935066
        axis 0 1 0
        anchor 0 0 0.075
      }
      device [
        RotationalMotor {
          name "right wheel motor"
          consumptionFactor 70
          maxVelocity 100
        }
        PositionSensor {
          name "right wheel sensor"
        }
      ]
      endPoint Solid {
        translation 0 -0.13499999999999668 0.075
        rotation 0.6846198636849928 -0.684619801544222 -0.25018267242455466 2.6512915227699576
        children [
          USE WHEEL
        ]
        name "right wheel"
        contactMaterial "roboWheel"
        boundingObject USE WHEEL
        physics USE PHYSICS_WHEEL
      }
    }
    DEF US0 DistanceSensor {
      translation 0.115 0.07 0.189
      rotation 0 0 -1 -0.499205
      children [
        DEF SONAR_SENSOR Pose {
          rotation 0.577656895078166 0.5771968951617173 -0.5771968951617173 -2.093935
          children [
            Shape {
              appearance PBRAppearance {
                baseColor 0.301961 0.301961 0.301961
                roughness 1
                metalness 0
              }
              geometry Cylinder {
                height 0.01
                radius 0.024
              }
            }
          ]
        }
      ]
      name "us0"
      lookupTable [
        0 0.7 0.01
        2 0 0
      ]
      type "sonar"
      numberOfRays 20
    }
    DEF US1 DistanceSensor {
      translation 0.115 -0.07 0.189
      rotation 0 0 1 -0.500795
      children [
        USE SONAR_SENSOR
      ]
      name "us1"
      lookupTable [
        0 0.7 0.1
        2 0 0
      ]
      type "sonar"
      numberOfRays 20
    }
    DEF LIDAR Lidar {
      translation 0 0 0.45
      children [
        Transform {
          translation 0 0 -0.01
          rotation 0 0 -1 1.570796
          scale 6 5 3
          children [
            DEF STRUCTURE_AXES Shape {
              appearance Appearance {
                material Material {
                  diffuseColor 0.02 0.02 0.02
                }
              }
              geometry IndexedLineSet {
                coord Coordinate {
                  point [
                    0 0 0.01
                    0.01 0 -0.08
                    -0.01 0 -0.08
                    0 0.01 -0.08
                    0 -0.01 -0.08
                  ]
                }
                coordIndex [
                  0, 1, 0, 2, 0, 3, 0, 4
                ]
              }
            }
          ]
        }
      ]
      horizontalResolution 128
      fieldOfView 1.57
      numberOfLayers 1
      near 0.05
      minRange 0.05
      maxRange 8
      defaultFrequency 2
      rotatingHead Solid {
        children [
          Pose {
            translation 0.03 0 0
            rotation 0 0 1 3.14159
            children [
              DEF LENS Shape {
                appearance PBRAppearance {
                  baseColor 0 0 0
                  roughness 1.1102230246251565e-16
                  metalness 0
                }
                geometry Sphere {
                  radius 0.015
                  subdivision 2
                }
              }
            ]
          }
          DEF CAMERA_SHAPE Pose {
            rotation -0.5771978956908259 0.5776548956082386 0.5771978956908259 -2.093935
            children [
              DEF CAMERA_OUTLINE Shape {
                appearance PBRAppearance {
                  baseColor 0.898039 0.898039 0.898039
                  roughness 1
                  metalness 0
                }
                geometry Cylinder {
                  height 0.06
                  radius 0.024
                }
              }
            ]
          }
        ]
      }
    }
  ]
  name "MyBot"
  contactMaterial "robo_body"
  boundingObject Pose {
    translation 0 0 0.1245
    rotation 0 0 1 -1.570796
    children [
      USE BODY
    ]
  }
  physics Physics {
    density -1
    mass 1.5
    centerOfMass [
      0 0 0.15
    ]
  }
  controller "webots_controller"
  supervisor TRUE
}
