#VRML_SIM R2023b utf8

EXTERNPROTO "https://raw.githubusercontent.com/cyberbotics/webots/R2023b/projects/objects/backgrounds/protos/TexturedBackground.proto"
EXTERNPROTO "https://raw.githubusercontent.com/cyberbotics/webots/R2023b/projects/objects/backgrounds/protos/TexturedBackgroundLight.proto"
EXTERNPROTO "https://raw.githubusercontent.com/cyberbotics/webots/R2023b/projects/objects/factory/containers/protos/WoodenBox.proto"
EXTERNPROTO "https://raw.githubusercontent.com/cyberbotics/webots/R2023b/projects/objects/floors/protos/Floor.proto"

WorldInfo {
  contactProperties [
    ContactProperties {
      material2 "dumbell"
      coulombFriction [
        0
      ]
      bounce 0
    }
  ]
}
Viewpoint {
  orientation 0.2209668141397301 0.5043176248050576 -0.8347678721416649 0.8161176518946822
  position -0.9155771238859559 0.5324938642660771 0.6781663664319371
  followType "None"
}
TexturedBackground {
  texture "twilight_cloudy_empty"
}
TexturedBackgroundLight {
}
WoodenBox {
  translation 0.99 2.22 0.5
  size 1 1 1
}
WoodenBox {
  translation 0.99 -3.11 0.5
  name "wooden box(1)"
  size 1 1 1
}
WoodenBox {
  translation -0.82 -0.5 0.05
  name "wooden box(2)"
  size 0.1 0.2 0.1
}
Floor {
}
Robot {
  translation 0 0 0.3
  children [
    DEF rWheel HingeJoint {
      jointParameters HingeJointParameters {
        axis 0 1 0
        anchor -0.0625 -0.1125 -0.025
      }
      device [
        RotationalMotor {
          name "right motor"
        }
      ]
      endPoint Solid {
        translation -0.0625 -0.1125 -0.025
        rotation 1 4.71026872516771e-16 7.850447875279518e-17 1.5707999999999998
        children [
          DEF WheelAcR Shape {
            appearance PBRAppearance {
              baseColor 0.427451 0.427451 0.427451
              baseColorMap ImageTexture {
                url [
                  "../../../Users/jckri/Pictures/Capture.PNG"
                ]
              }
              metalness 0
            }
            geometry Cylinder {
              height 0.025
              radius 0.05
            }
          }
        ]
        name "solid(2)"
        boundingObject USE WheelAcR
        physics DEF WHEEL_PH Physics {
        }
      }
    }
    DEF RoboCoreBlock Shape {
      appearance PBRAppearance {
      }
      geometry Box {
        size 0.125 0.2 0.1
      }
    }
    DEF lWheel HingeJoint {
      jointParameters HingeJointParameters {
        axis 0 1 0
        anchor -0.0625 0.1125 -0.025
      }
      device [
        DEF WheelLeft RotationalMotor {
          name "left motor"
        }
      ]
      endPoint Solid {
        translation -0.0625 0.1125 -0.025
        rotation 1 4.71026872516771e-16 7.850447875279518e-17 1.5707999999999998
        children [
          DEF WheelAcL Shape {
            appearance PBRAppearance {
              baseColor 0.427451 0.427451 0.427451
              baseColorMap ImageTexture {
                url [
                  "../../../Users/jckri/Pictures/Capture.PNG"
                ]
              }
              metalness 0
            }
            geometry Cylinder {
              height 0.025
              radius 0.05
            }
          }
        ]
        name "solid(1)"
        boundingObject USE WheelAcL
        physics DEF WHEEL_PH Physics {
        }
      }
    }
  ]
  boundingObject DEF RoboCoreBlock Shape {
    appearance PBRAppearance {
    }
    geometry Box {
      size 0.125 0.2 0.1
    }
  }
  physics Physics {
  }
}
Solid {
  translation 0 1.2 0.63
  children [
    DEF DBG1 Group {
      children [
        Shape {
          geometry Cylinder {
            height 0.4
            radius 0.03
          }
        }
        Pose {
          translation 0 0 -0.2
          children [
            Shape {
              appearance PBRAppearance {
              }
              geometry Sphere {
                radius 0.1
              }
            }
          ]
        }
        Pose {
          translation 0 0 0.2
          children [
            Shape {
              appearance PBRAppearance {
                metalness 0.2
              }
              geometry Sphere {
                radius 0.1
              }
            }
          ]
        }
      ]
    }
  ]
  name "dunbell"
  contactMaterial "dumbell"
  boundingObject USE DBG1
  physics Physics {
    mass 2
    centerOfMass [
      0 0 0.2
    ]
  }
}
Solid {
  translation -5 0 0.25
  children [
    Shape {
      appearance PBRAppearance {
        baseColor 0.666667 0 0
        metalness 0.1
      }
      geometry DEF Wall1 Box {
        size 0.5 10 0.5
      }
    }
  ]
  name "solid(1)"
  boundingObject USE Wall1
}
Solid {
  translation 5.26 0 0.25
  children [
    Shape {
      appearance PBRAppearance {
        baseColor 0.666667 0 0
        metalness 0.1
      }
      geometry DEF Wall1 Box {
        size 0.5 10 0.5
      }
    }
  ]
  name "solid(2)"
  boundingObject USE Wall1
}
Solid {
  translation 0.26 5.25 0.25
  rotation 0 0 1 -1.5707953071795862
  children [
    Shape {
      appearance PBRAppearance {
        baseColor 0.666667 0 0
        metalness 0.1
      }
      geometry DEF Wall1 Box {
        size 0.5 10 0.5
      }
    }
  ]
  name "solid(3)"
  boundingObject USE Wall1
}
Solid {
  translation 0.260001 -5.26 0.25
  rotation 0 0 1 -1.5707953071795862
  children [
    Shape {
      appearance PBRAppearance {
        baseColor 0.666667 0 0
        metalness 0.1
      }
      geometry DEF Wall1 Box {
        size 0.5 10 0.5
      }
    }
  ]
  name "solid(4)"
  boundingObject USE Wall1
}
Solid {
  translation 0.17 -0.8 0.43
  children [
    DEF ballShape Shape {
      appearance PBRAppearance {
        baseColorMap ImageTexture {
          url [
            "../../../Users/jckri/Downloads/51f3da99-7502-4d4e-a1ee-8b20ddec8fdb-amongstus-1826565804.jpg"
          ]
        }
      }
      geometry Sphere {
        radius 0.1
        subdivision 3
      }
    }
  ]
  boundingObject USE ballShape
  physics Physics {
  }
}
